Workbook
Name SPYTrendScore: [1]TradeRadar!XFC1048537

Sheet Watchlist
A1: Symbol | B1: Price | C1: RSI | D1: RVOL | E1: TrendScore | F1: Return3M | G1: Dist52High | H1: StopPrice | I1: TargetPrice | J1: RewardRisk | K1: AlphaScore | L1: Rank | M1: Grade | N1: Decision | O1: SMAScore | P1: Breakout? | Q1: Pullback? | R1: PullbackScore
A2: =Indicators!A2 | B2: =Indicators!C2 | C2: =Indicators!G2 | D2: =Indicators!H2 | E2: =Indicators!J2 | F2: =Indicators!K2 | G2: =Indicators!L2 | H2: =B2-(Indicators!I2*1.5) | I2: =B2+(Indicators!I2*3) | J2: =(I2-B2)/(B2-H2) | K2: =(E2*0.5)+ (F2*0.2)+ ((100+G2)*0.1)+ (MIN(J2,3)*10) | L2: =RANK(K2,$K$2:$K$100,0) | M2: =IF(K2>=80,"A", IF(K2>=70,"B", IF(K2>=60,"C", "F"))) | N2: =IF(K2>=75,"BUY NOW", IF(K2>=60,"WATCH", "AVOID")) | O2: =(B2>Indicators!D2)+ (B2>Indicators!E2)+ (B2>Indicators!F2) | P2: =IF( AND( K2>=80, C2>=50, F2>0 ), "YES", "NO" ) | Q2: =IF( AND( B2>Indicators!F2, ABS(B2-Indicators!D2)/Indicators!D2<0.03 ), "YES", "NO" ) | R2: =IF(ABS(B2-Indicators!D2)/Indicators!D2<0.02,40,0) + IF(B2>Indicators!E2,30,0) + IF(B2>Indicators!F2,30,0)
A3: =Indicators!A3 | B3: =Indicators!C3 | C3: =Indicators!G3 | D3: =Indicators!H3 | E3: =Indicators!J3 | F3: =Indicators!K3 | G3: =Indicators!L3 | H3: =B3-(Indicators!I3*1.5) | I3: =B3+(Indicators!I3*3) | J3: =(I3-B3)/(B3-H3) | K3: =(E3*0.5)+ (F3*0.2)+ ((100+G3)*0.1)+ (MIN(J3,3)*10) | L3: =RANK(K3,$K$2:$K$100,0) | M3: =IF(K3>=80,"A", IF(K3>=70,"B", IF(K3>=60,"C", "F"))) | N3: =IF(K3>=75,"BUY NOW", IF(K3>=60,"WATCH", "AVOID")) | O3: =(B3>Indicators!D3)+ (B3>Indicators!E3)+ (B3>Indicators!F3) | P3: =IF( AND( K3>=80, C3>=50, F3> 0), "YES", "NO" ) | Q3: =IF( AND( B3>Indicators!F3, ABS(B3-Indicators!D3)/Indicators!D3<0.03 ), "YES", "NO" ) | R3: =IF(ABS(B3-Indicators!D3)/Indicators!D3<0.02,40,0) + IF(B3>Indicators!E3,30,0) + IF(B3>Indicators!F3,30,0)
A4: =Indicators!A4 | B4: =Indicators!C4 | C4: =Indicators!G4 | D4: =Indicators!H4 | E4: =Indicators!J4 | F4: =Indicators!K4 | G4: =Indicators!L4 | H4: =B4-(Indicators!I4*1.5) | I4: =B4+(Indicators!I4*3) | J4: =(I4-B4)/(B4-H4) | K4: =(E4*0.5)+ (F4*0.2)+ ((100+G4)*0.1)+ (MIN(J4,3)*10) | L4: =RANK(K4,$K$2:$K$100,0) | M4: =IF(K4>=80,"A", IF(K4>=70,"B", IF(K4>=60,"C", "F"))) | N4: =IF(K4>=75,"BUY NOW", IF(K4>=60,"WATCH", "AVOID")) | O4: =(B4>Indicators!D4)+ (B4>Indicators!E4)+ (B4>Indicators!F4) | P4: =IF( AND( K4>=80, C4>=50, F4> 0), "YES", "NO" ) | Q4: =IF( AND( B4>Indicators!F4, ABS(B4-Indicators!D4)/Indicators!D4<0.03 ), "YES", "NO" ) | R4: =IF(ABS(B4-Indicators!D4)/Indicators!D4<0.02,40,0) + IF(B4>Indicators!E4,30,0) + IF(B4>Indicators!F4,30,0)
A5: =Indicators!A5 | B5: =Indicators!C5 | C5: =Indicators!G5 | D5: =Indicators!H5 | E5: =Indicators!J5 | F5: =Indicators!K5 | G5: =Indicators!L5 | H5: =B5-(Indicators!I5*1.5) | I5: =B5+(Indicators!I5*3) | J5: =(I5-B5)/(B5-H5) | K5: =(E5*0.5)+ (F5*0.2)+ ((100+G5)*0.1)+ (MIN(J5,3)*10) | L5: =RANK(K5,$K$2:$K$100,0) | M5: =IF(K5>=80,"A", IF(K5>=70,"B", IF(K5>=60,"C", "F"))) | N5: =IF(K5>=75,"BUY NOW", IF(K5>=60,"WATCH", "AVOID")) | O5: =(B5>Indicators!D5)+ (B5>Indicators!E5)+ (B5>Indicators!F5) | P5: =IF( AND( K5>=80, C5>=50, F5> 0), "YES", "NO" ) | Q5: =IF( AND( B5>Indicators!F5, ABS(B5-Indicators!D5)/Indicators!D5<0.03 ), "YES", "NO" ) | R5: =IF(ABS(B5-Indicators!D5)/Indicators!D5<0.02,40,0) + IF(B5>Indicators!E5,30,0) + IF(B5>Indicators!F5,30,0)
A6: =Indicators!A6 | B6: =Indicators!C6 | C6: =Indicators!G6 | D6: =Indicators!H6 | E6: =Indicators!J6 | F6: =Indicators!K6 | G6: =Indicators!L6 | H6: =B6-(Indicators!I6*1.5) | I6: =B6+(Indicators!I6*3) | J6: =(I6-B6)/(B6-H6) | K6: =(E6*0.5)+ (F6*0.2)+ ((100+G6)*0.1)+ (MIN(J6,3)*10) | L6: =RANK(K6,$K$2:$K$100,0) | M6: =IF(K6>=80,"A", IF(K6>=70,"B", IF(K6>=60,"C", "F"))) | N6: =IF(K6>=75,"BUY NOW", IF(K6>=60,"WATCH", "AVOID")) | O6: =(B6>Indicators!D6)+ (B6>Indicators!E6)+ (B6>Indicators!F6) | P6: =IF( AND( K6>=80, C6>=50, F6> 0), "YES", "NO" ) | Q6: =IF( AND( B6>Indicators!F6, ABS(B6-Indicators!D6)/Indicators!D6<0.03 ), "YES", "NO" ) | R6: =IF(ABS(B6-Indicators!D6)/Indicators!D6<0.02,40,0) + IF(B6>Indicators!E6,30,0) + IF(B6>Indicators!F6,30,0)
A7: =Indicators!A7 | B7: =Indicators!C7 | C7: =Indicators!G7 | D7: =Indicators!H7 | E7: =Indicators!J7 | F7: =Indicators!K7 | G7: =Indicators!L7 | H7: =B7-(Indicators!I7*1.5) | I7: =B7+(Indicators!I7*3) | J7: =(I7-B7)/(B7-H7) | K7: =(E7*0.5)+ (F7*0.2)+ ((100+G7)*0.1)+ (MIN(J7,3)*10) | L7: =RANK(K7,$K$2:$K$100,0) | M7: =IF(K7>=80,"A", IF(K7>=70,"B", IF(K7>=60,"C", "F"))) | N7: =IF(K7>=75,"BUY NOW", IF(K7>=60,"WATCH", "AVOID")) | O7: =(B7>Indicators!D7)+ (B7>Indicators!E7)+ (B7>Indicators!F7) | P7: =IF( AND( K7>=80, C7>=50, F7> 0), "YES", "NO" ) | Q7: =IF( AND( B7>Indicators!F7, ABS(B7-Indicators!D7)/Indicators!D7<0.03 ), "YES", "NO" ) | R7: =IF(ABS(B7-Indicators!D7)/Indicators!D7<0.02,40,0) + IF(B7>Indicators!E7,30,0) + IF(B7>Indicators!F7,30,0)
A8: =Indicators!A8 | B8: =Indicators!C8 | C8: =Indicators!G8 | D8: =Indicators!H8 | E8: =Indicators!J8 | F8: =Indicators!K8 | G8: =Indicators!L8 | H8: =B8-(Indicators!I8*1.5) | I8: =B8+(Indicators!I8*3) | J8: =(I8-B8)/(B8-H8) | K8: =(E8*0.5)+ (F8*0.2)+ ((100+G8)*0.1)+ (MIN(J8,3)*10) | L8: =RANK(K8,$K$2:$K$100,0) | M8: =IF(K8>=80,"A", IF(K8>=70,"B", IF(K8>=60,"C", "F"))) | N8: =IF(K8>=75,"BUY NOW", IF(K8>=60,"WATCH", "AVOID")) | O8: =(B8>Indicators!D8)+ (B8>Indicators!E8)+ (B8>Indicators!F8) | P8: =IF( AND( K8>=80, C8>=50, F8> 0), "YES", "NO" ) | Q8: =IF( AND( B8>Indicators!F8, ABS(B8-Indicators!D8)/Indicators!D8<0.03 ), "YES", "NO" ) | R8: =IF(ABS(B8-Indicators!D8)/Indicators!D8<0.02,40,0) + IF(B8>Indicators!E8,30,0) + IF(B8>Indicators!F8,30,0)
A9: =Indicators!A9 | B9: =Indicators!C9 | C9: =Indicators!G9 | D9: =Indicators!H9 | E9: =Indicators!J9 | F9: =Indicators!K9 | G9: =Indicators!L9 | H9: =B9-(Indicators!I9*1.5) | I9: =B9+(Indicators!I9*3) | J9: =(I9-B9)/(B9-H9) | K9: =(E9*0.5)+ (F9*0.2)+ ((100+G9)*0.1)+ (MIN(J9,3)*10) | L9: =RANK(K9,$K$2:$K$100,0) | M9: =IF(K9>=80,"A", IF(K9>=70,"B", IF(K9>=60,"C", "F"))) | N9: =IF(K9>=75,"BUY NOW", IF(K9>=60,"WATCH", "AVOID")) | O9: =(B9>Indicators!D9)+ (B9>Indicators!E9)+ (B9>Indicators!F9) | P9: =IF( AND( K9>=80, C9>=50, F9> 0), "YES", "NO" ) | Q9: =IF( AND( B9>Indicators!F9, ABS(B9-Indicators!D9)/Indicators!D9<0.03 ), "YES", "NO" ) | R9: =IF(ABS(B9-Indicators!D9)/Indicators!D9<0.02,40,0) + IF(B9>Indicators!E9,30,0) + IF(B9>Indicators!F9,30,0)
A10: =Indicators!A10 | B10: =Indicators!C10 | C10: =Indicators!G10 | D10: =Indicators!H10 | E10: =Indicators!J10 | F10: =Indicators!K10 | G10: =Indicators!L10 | H10: =B10-(Indicators!I10*1.5) | I10: =B10+(Indicators!I10*3) | J10: =(I10-B10)/(B10-H10) | K10: =(E10*0.5)+ (F10*0.2)+ ((100+G10)*0.1)+ (MIN(J10,3)*10) | L10: =RANK(K10,$K$2:$K$100,0) | M10: =IF(K10>=80,"A", IF(K10>=70,"B", IF(K10>=60,"C", "F"))) | N10: =IF(K10>=75,"BUY NOW", IF(K10>=60,"WATCH", "AVOID")) | O10: =(B10>Indicators!D10)+ (B10>Indicators!E10)+ (B10>Indicators!F10) | P10: =IF( AND( K10>=80, C10>=50, F10> 0), "YES", "NO" ) | Q10: =IF( AND( B10>Indicators!F10, ABS(B10-Indicators!D10)/Indicators!D10<0.03 ), "YES", "NO" ) | R10: =IF(ABS(B10-Indicators!D10)/Indicators!D10<0.02,40,0) + IF(B10>Indicators!E10,30,0) + IF(B10>Indicators!F10,30,0)
A11: =Indicators!A11 | B11: =Indicators!C11 | C11: =Indicators!G11 | D11: =Indicators!H11 | E11: =Indicators!J11 | F11: =Indicators!K11 | G11: =Indicators!L11 | H11: =B11-(Indicators!I11*1.5) | I11: =B11+(Indicators!I11*3) | J11: =(I11-B11)/(B11-H11) | K11: =(E11*0.5)+ (F11*0.2)+ ((100+G11)*0.1)+ (MIN(J11,3)*10) | L11: =RANK(K11,$K$2:$K$100,0) | M11: =IF(K11>=80,"A", IF(K11>=70,"B", IF(K11>=60,"C", "F"))) | N11: =IF(K11>=75,"BUY NOW", IF(K11>=60,"WATCH", "AVOID")) | O11: =(B11>Indicators!D11)+ (B11>Indicators!E11)+ (B11>Indicators!F11) | P11: =IF( AND( K11>=80, C11>=50, F11> 0), "YES", "NO" ) | Q11: =IF( AND( B11>Indicators!F11, ABS(B11-Indicators!D11)/Indicators!D11<0.03 ), "YES", "NO" ) | R11: =IF(ABS(B11-Indicators!D11)/Indicators!D11<0.02,40,0) + IF(B11>Indicators!E11,30,0) + IF(B11>Indicators!F11,30,0)
A12: =Indicators!A12 | B12: =Indicators!C12 | C12: =Indicators!G12 | D12: =Indicators!H12 | E12: =Indicators!J12 | F12: =Indicators!K12 | G12: =Indicators!L12 | H12: =B12-(Indicators!I12*1.5) | I12: =B12+(Indicators!I12*3) | J12: =(I12-B12)/(B12-H12) | K12: =(E12*0.5)+ (F12*0.2)+ ((100+G12)*0.1)+ (MIN(J12,3)*10) | L12: =RANK(K12,$K$2:$K$100,0) | M12: =IF(K12>=80,"A", IF(K12>=70,"B", IF(K12>=60,"C", "F"))) | N12: =IF(K12>=75,"BUY NOW", IF(K12>=60,"WATCH", "AVOID")) | O12: =(B12>Indicators!D12)+ (B12>Indicators!E12)+ (B12>Indicators!F12) | P12: =IF( AND( K12>=80, C12>=50, F12> 0), "YES", "NO" ) | Q12: =IF( AND( B12>Indicators!F12, ABS(B12-Indicators!D12)/Indicators!D12<0.03 ), "YES", "NO" ) | R12: =IF(ABS(B12-Indicators!D12)/Indicators!D12<0.02,40,0) + IF(B12>Indicators!E12,30,0) + IF(B12>Indicators!F12,30,0)
A13: =Indicators!A13 | B13: =Indicators!C13 | C13: =Indicators!G13 | D13: =Indicators!H13 | E13: =Indicators!J13 | F13: =Indicators!K13 | G13: =Indicators!L13 | H13: =B13-(Indicators!I13*1.5) | I13: =B13+(Indicators!I13*3) | J13: =(I13-B13)/(B13-H13) | K13: =(E13*0.5)+ (F13*0.2)+ ((100+G13)*0.1)+ (MIN(J13,3)*10) | L13: =RANK(K13,$K$2:$K$100,0) | M13: =IF(K13>=80,"A", IF(K13>=70,"B", IF(K13>=60,"C", "F"))) | N13: =IF(K13>=75,"BUY NOW", IF(K13>=60,"WATCH", "AVOID")) | O13: =(B13>Indicators!D13)+ (B13>Indicators!E13)+ (B13>Indicators!F13) | P13: =IF( AND( K13>=80, C13>=50, F13> 0), "YES", "NO" ) | Q13: =IF( AND( B13>Indicators!F13, ABS(B13-Indicators!D13)/Indicators!D13<0.03 ), "YES", "NO" ) | R13: =IF(ABS(B13-Indicators!D13)/Indicators!D13<0.02,40,0) + IF(B13>Indicators!E13,30,0) + IF(B13>Indicators!F13,30,0)
A14: =Indicators!A14 | B14: =Indicators!C14 | C14: =Indicators!G14 | D14: =Indicators!H14 | E14: =Indicators!J14 | F14: =Indicators!K14 | G14: =Indicators!L14 | H14: =B14-(Indicators!I14*1.5) | I14: =B14+(Indicators!I14*3) | J14: =(I14-B14)/(B14-H14) | K14: =(E14*0.5)+ (F14*0.2)+ ((100+G14)*0.1)+ (MIN(J14,3)*10) | L14: =RANK(K14,$K$2:$K$100,0) | M14: =IF(K14>=80,"A", IF(K14>=70,"B", IF(K14>=60,"C", "F"))) | N14: =IF(K14>=75,"BUY NOW", IF(K14>=60,"WATCH", "AVOID")) | O14: =(B14>Indicators!D14)+ (B14>Indicators!E14)+ (B14>Indicators!F14) | P14: =IF( AND( K14>=80, C14>=50, F14> 0), "YES", "NO" ) | Q14: =IF( AND( B14>Indicators!F14, ABS(B14-Indicators!D14)/Indicators!D14<0.03 ), "YES", "NO" ) | R14: =IF(ABS(B14-Indicators!D14)/Indicators!D14<0.02,40,0) + IF(B14>Indicators!E14,30,0) + IF(B14>Indicators!F14,30,0)
... A36: =Indicators!A36 | B36: =Indicators!C36 | C36: =Indicators!G36 | D36: =Indicators!H36 | E36: =Indicators!J36 | F36: =Indicators!K36 | G36: =Indicators!L36 | H36: =B36-(Indicators!I36*1.5) | I36: =B36+(Indicators!I36*3) | J36: =(I36-B36)/(B36-H36) | K36: =(E36*0.5)+ (F36*0.2)+ ((100+G36)*0.1)+ (MIN(J36,3)*10) | L36: =RANK(K36,$K$2:$K$100,0) | M36: =IF(K36>=80,"A", IF(K36>=70,"B", IF(K36>=60,"C", "F"))) | N36: =IF(K36>=75,"BUY NOW", IF(K36>=60,"WATCH", "AVOID")) | O36: =(B36>Indicators!D36)+ (B36>Indicators!E36)+ (B36>Indicators!F36) | P36: =IF( AND( K36>=80, C36>=50, F36> 0), "YES", "NO" ) | Q36: =IF( AND( B36>Indicators!F36, ABS(B36-Indicators!D36)/Indicators!D36<0.03 ), "YES", "NO" ) | R36: =IF(ABS(B36-Indicators!D36)/Indicators!D36<0.02,40,0) + IF(B36>Indicators!E36,30,0) + IF(B36>Indicators!F36,30,0)

Sheet EliteLeaders
A1: Rank | B1: Symbol | C1: Date | D1: Price | E1: RSI | F1: RVOL | G1: Return3M | H1: Dist52High | I1: TrendScore | J1: EntryScore | K1: AlphaScore | L1: EliteLeader | M1: InstitutionalAccumulation | N1: Decision
A2: 1 | B2: FBRX | C2: 2026-07-30 | D2: 76.57 | E2: 84.5 | F2: 0.81 | G2: 187.19 | H2: -0.11 | I2: 60 | J2: 45 | K2: 100 | L2: TRUE | M2: FALSE | N2: ELITE LEADER
A3: 2 | B3: CORT | C3: 2026-07-30 | D3: 117.5 | E3: 70.5 | F3: 2.6 | G3: 152.57 | H3: 0 | I3: 60 | J3: 60 | K3: 100 | L3: TRUE | M3: FALSE | N3: ELITE LEADER
A4: 3 | B4: TXG | C4: 2026-07-30 | D4: 48.93 | E4: 66.06 | F4: 0.5 | G4: 121.9 | H4: 0 | I4: 60 | J4: 45 | K4: 100 | L4: TRUE | M4: FALSE | N4: ELITE LEADER
A5: 4 | B5: CRNX | C5: 2026-07-30 | D5: 83.81 | E5: 61.86 | F5: 0.13 | G5: 116.12 | H5: -0.12 | I5: 60 | J5: 70 | K5: 100 | L5: TRUE | M5: FALSE | N5: ELITE LEADER
A6: 7 | B6: BJRI | C6: 2026-07-30 | D6: 71.85 | E6: 73.2 | F6: 0.85 | G6: 87.11 | H6: 0 | I6: 60 | J6: 45 | K6: 100 | L6: TRUE | M6: FALSE | N6: ELITE LEADER
A7: 11 | B7: XNCR | C7: 2026-07-30 | D7: 21.41 | E7: 76.83 | F7: 0.89 | G7: 79.46 | H7: 0 | I7: 60 | J7: 45 | K7: 100 | L7: TRUE | M7: FALSE | N7: ELITE LEADER
A8: 12 | B8: VCYT | C8: 2026-07-30 | D8: 58.69 | E8: 55.46 | F8: 1.09 | G8: 78.3 | H8: -2.97 | I8: 60 | J8: 100 | K8: 100 | L8: TRUE | M8: FALSE | N8: ELITE LEADER
A9: 14 | B9: LPRO | C9: 2026-07-30 | D9: 3.14 | E9: 54.55 | F9: 0.47 | G9: 77.4 | H9: -0.32 | I9: 60 | J9: 85 | K9: 100 | L9: TRUE | M9: FALSE | N9: ELITE LEADER
A10: 17 | B10: BRKR | C10: 2026-07-30 | D10: 63.85 | E10: 58.45 | F10: 0.62 | G10: 74.07 | H10: 0 | I10: 60 | J10: 70 | K10: 100 | L10: TRUE | M10: FALSE | N10: ELITE LEADER
A11: 19 | B11: NEO | C11: 2026-07-30 | D11: 15.76 | E11: 63.91 | F11: 1.14 | G11: 70.19 | H11: 0 | I11: 60 | J11: 85 | K11: 100 | L11: TRUE | M11: FALSE | N11: ELITE LEADER
A12: 20 | B12: PLSE | C12: 2026-07-30 | D12: 35.6 | E12: 75.2 | F12: 0.48 | G12: 68.16 | H12: 0 | I12: 60 | J12: 45 | K12: 100 | L12: TRUE | M12: FALSE | N12: ELITE LEADER
A13: 22 | B13: ADPT | C13: 2026-07-30 | D13: 23.53 | E13: 66.14 | F13: 1.24 | G13: 66.88 | H13: 0 | I13: 60 | J13: 60 | K13: 100 | L13: TRUE | M13: FALSE | N13: ELITE LEADER
... A18: 33 | B18: BLFS | C18: 2026-07-30 | D18: 31.66 | E18: 68.01 | F18: 0.11 | G18: 50.19 | H18: -1 | I18: 60 | J18: 45 | K18: 100 | L18: TRUE | M18: FALSE | N18: ELITE LEADER

Sheet InstitutionalAccumulation
A1: Rank | B1: Symbol | C1: Date | D1: Price | E1: RSI | F1: RVOL | G1: Return3M | H1: Dist52High | I1: TrendScore | J1: EntryScore | K1: AlphaScore | L1: EliteLeader | M1: InstitutionalAccumulation | N1: Decision

Sheet TradeDashRankings
A1: Rank | B1: Symbol | C1: Date | D1: Price | E1: RSI | F1: RVOL | G1: Return3M | H1: Dist52High | I1: TrendScore | J1: EntryScore | K1: AlphaScore | L1: EliteLeader | M1: InstitutionalAccumulation | N1: Decision
A2: 1 | B2: FBRX | C2: 2026-07-30 | D2: 76.57 | E2: 84.5 | F2: 0.81 | G2: 187.19 | H2: -0.11 | I2: 60 | J2: 45 | K2: 100 | L2: TRUE | M2: FALSE | N2: ELITE LEADER
A3: 2 | B3: CORT | C3: 2026-07-30 | D3: 117.5 | E3: 70.5 | F3: 2.6 | G3: 152.57 | H3: 0 | I3: 60 | J3: 60 | K3: 100 | L3: TRUE | M3: FALSE | N3: ELITE LEADER
A4: 3 | B4: TXG | C4: 2026-07-30 | D4: 48.93 | E4: 66.06 | F4: 0.5 | G4: 121.9 | H4: 0 | I4: 60 | J4: 45 | K4: 100 | L4: TRUE | M4: FALSE | N4: ELITE LEADER
A5: 4 | B5: CRNX | C5: 2026-07-30 | D5: 83.81 | E5: 61.86 | F5: 0.13 | G5: 116.12 | H5: -0.12 | I5: 60 | J5: 70 | K5: 100 | L5: TRUE | M5: FALSE | N5: ELITE LEADER
A6: 5 | B6: DDOG | C6: 2026-07-30 | D6: 266.61 | E6: 56.24 | F6: 0.64 | G6: 101.69 | H6: -3.92 | I6: 60 | J6: 70 | K6: 100 | L6: FALSE | M6: FALSE | N6: HIGH CONVICTION
A7: 6 | B7: GRPN | C7: 2026-07-30 | D7: 27.66 | E7: 54.31 | F7: 0.51 | G7: 94.65 | H7: -25.02 | I7: 60 | J7: 70 | K7: 100 | L7: FALSE | M7: FALSE | N7: HIGH CONVICTION
A8: 7 | B8: BJRI | C8: 2026-07-30 | D8: 71.85 | E8: 73.2 | F8: 0.85 | G8: 87.11 | H8: 0 | I8: 60 | J8: 45 | K8: 100 | L8: TRUE | M8: FALSE | N8: ELITE LEADER
A9: 8 | B9: FTNT | C9: 2026-07-30 | D9: 153.99 | E9: 44.75 | F9: 1.41 | G9: 82.65 | H9: -7.7 | I9: 45 | J9: 75 | K9: 100 | L9: FALSE | M9: FALSE | N9: HIGH CONVICTION
A10: 9 | B10: MRVI | C10: 2026-07-30 | D10: 6.7 | E10: 62.35 | F10: 0.23 | G10: 82.07 | H10: -7.46 | I10: 60 | J10: 85 | K10: 100 | L10: FALSE | M10: FALSE | N10: HIGH CONVICTION
A11: 10 | B11: CBRL | C11: 2026-07-30 | D11: 56.54 | E11: 67.58 | F11: 0.42 | G11: 81.41 | H11: -7.19 | I11: 60 | J11: 45 | K11: 100 | L11: FALSE | M11: FALSE | N11: HIGH CONVICTION
A12: 11 | B12: XNCR | C12: 2026-07-30 | D12: 21.41 | E12: 76.83 | F12: 0.89 | G12: 79.46 | H12: 0 | I12: 60 | J12: 45 | K12: 100 | L12: TRUE | M12: FALSE | N12: ELITE LEADER
A13: 12 | B13: VCYT | C13: 2026-07-30 | D13: 58.69 | E13: 55.46 | F13: 1.09 | G13: 78.3 | H13: -2.97 | I13: 60 | J13: 100 | K13: 100 | L13: TRUE | M13: FALSE | N13: ELITE LEADER
... A809: 808 | B809: CRMT | C809: 2026-07-30 | D809: 3.19 | E809: 49.41 | F809: 0.15 | G809: -73.87 | H809: -93.28 | I809: 0 | J809: 25 | K809: 0 | L809: FALSE | M809: FALSE | N809: AVOID

Sheet Market Dashboard
A1: MARKET HEALTH
A2: SPY | B2: =_xlfn.XLOOKUP("SPY",Indicators!A:A,Indicators!J:J)
A3: QQQ | B3: =_xlfn.XLOOKUP("QQQ",Indicators!A:A,Indicators!J:J)
A4: IWM | B4: =_xlfn.XLOOKUP("IWM",Indicators!A:A,Indicators!J:J)
A6: Score | B6: =AVERAGE(B2:B4)
A7: Regime | B7: =IF(B6>=70,"BULLISH", IF(B6>=50,"NEUTRAL", "BEARISH"))

Sheet Indicators
A1: Symbol | B1: Date | C1: Price | D1: RSI | E1: RVOL | F1: Return3M | G1: Dist52High | H1: TrendScore | I1: EntryScore | J1: AlphaScore | K1: EliteLeader | L1: InstitutionalAccumulation | M1: Decision
A2: AAL | B2: 2026-07-30 | C2: 15.32 | D2: 38.04 | E2: 0.28 | F2: 30.87 | G2: -15.56 | H2: 35 | I2: 40 | J2: 65 | K2: FALSE | L2: FALSE | M2: AVOID
A3: AAON | B3: 2026-07-30 | C3: 87.82 | D3: 18.55 | E3: 0.83 | F3: -5.81 | G3: -40.72 | H3: 10 | I3: 0 | J3: 10 | K3: FALSE | L3: FALSE | M3: AVOID
A4: AAPL | B4: 2026-07-30 | C4: 333.92 | D4: 64.93 | E4: 0.74 | F4: 23.17 | G4: -1.81 | H4: 60 | I4: 85 | J4: 100 | K4: FALSE | L4: FALSE | M4: HIGH CONVICTION
A5: ABCB | B5: 2026-07-30 | C5: 87.96 | D5: 40.66 | E5: 0.25 | F5: 3.4 | G5: -5.6 | H5: 45 | I5: 60 | J5: 55 | K5: FALSE | L5: FALSE | M5: AVOID
A6: ABCL | B6: 2026-07-30 | C6: 5.53 | D6: 30.39 | E6: 0.53 | F6: 33.37 | G6: -31.83 | H6: 35 | I6: 25 | J6: 65 | K6: FALSE | L6: FALSE | M6: AVOID
A7: ABNB | B7: 2026-07-30 | C7: 151.75 | D7: 54.88 | E7: 0.38 | F7: 8.11 | G7: -0.89 | H7: 60 | I7: 70 | J7: 90 | K7: FALSE | L7: FALSE | M7: WATCH
A8: ACAD | B8: 2026-07-30 | C8: 26.44 | D8: 52.42 | E8: 0.57 | F8: 17.77 | G8: -5.77 | H8: 50 | I8: 85 | J8: 70 | K8: FALSE | L8: FALSE | M8: AVOID
A9: ACGL | B9: 2026-07-30 | C9: 100.4 | D9: 48.78 | E9: 0.61 | F9: 6.29 | G9: -5.71 | H9: 45 | I9: 85 | J9: 55 | K9: FALSE | L9: FALSE | M9: AVOID
A10: ACHC | B10: 2026-07-30 | C10: 28.59 | D10: 42.01 | E10: 0.54 | F10: 10.41 | G10: -19.7 | H10: 45 | I10: 45 | J10: 55 | K10: FALSE | L10: FALSE | M10: AVOID
A11: ACIW | B11: 2026-07-30 | C11: 58.06 | D11: 54.88 | E11: 0.39 | F11: 34.34 | G11: -3.52 | H11: 60 | I11: 85 | J11: 100 | K11: FALSE | L11: FALSE | M11: HIGH CONVICTION
A12: ACLS | B12: 2026-07-30 | C12: 125.67 | D12: 39.58 | E12: 0.38 | F12: -9.67 | G12: -34.41 | H12: 25 | I12: 25 | J12: 25 | K12: FALSE | L12: FALSE | M12: AVOID
A13: ACMR | B13: 2026-07-30 | C13: 77.47 | D13: 34.99 | E13: 0.94 | F13: 49.88 | G13: -38.94 | H13: 25 | I13: 25 | J13: 55 | K13: FALSE | L13: FALSE | M13: AVOID
... A809: ZS | B809: 2026-07-30 | C809: 147.57 | D809: 57.9 | E809: 0.83 | F809: 12.92 | G809: -56.12 | H809: 35 | I809: 60 | J809: 45 | K809: FALSE | L809: FALSE | M809: AVOID

Sheet TickerUniverse
A1: Symbol
A2: SNOW
A3: DDOG
A4: FTNT
A5: NET
A6: ABBV
A7: AAPL
A8: BAC
A9: JPM
A10: TGT
A11: ROST
A12: SBUX
... A17: CRWD

Sheet Trade Journal
A1: Date | B1: Symbol | C1: Entry | D1: Stop | E1: Target | F1: Exit | G1: P/L | K1: Date | L1: Symbol | M1: Score | N1: Grade | O1: Reason Entered | P1: Entry | Q1: Stop | R1: Target | S1: Exit | T1: Win/Loss
K2: 46226 | L2: SNOW | M2: 84 | N2: A | O2: Test | P2: 263.11 | Q2: 243.3 | R2: 301.71
K3: 46227 | L3: ABBV | M3: 81.3 | N3: A | O3: Test | P3: 259.32 | Q3: 250.86 | R3: 276.74
K4: 46228 | L4: PH | M4: 75.1 | N4: B | O4: Test | P4: 991.82 | Q4: 957.31 | R4: 1060.85
O5: Test
O6: Test
O7: Test
O8: Test
O9: Test
O10: Test
O11: Test
O12: Test
O13: Test
O14: Test
O15: Test
O16: Test
... O30: Test

Sheet Risk Calculator
A1: Account Size | B1: 10000
A2: Risk % | B2: 0.01
A3: Entry Price | B3: 50
A4: Stop Price | B4: 48
A5: Dollar Risk | B5: =B1*B2
A6: Risk Per Share | B6: =B3-B4
A7: Shares To Buy | B7: =B5/B6

Sheet Trade Radar
A1: Trade Radar
A2: Market Status | E2: Elite Leaders | G2: =MAX(COUNTA(EliteLeaders!A:A)-1,0)
A3: Score | B3: ='Market Dashboard'!B6 | E3: Institutional Count | G3: =MAX(COUNTA(InstitutionalAccumulation!A:A)-1,0)
A4: Regime | B4: ='Market Dashboard'!B7 | E4: High Conviction | G4: =COUNTIF(Indicators!J:J,">=95")
L8: MARKET SUMMARY
L9: =IF(COUNTIF(Watchlist!O:O,"BUY NOW")>=8, "STRONG BUY", IF(COUNTIF(Watchlist!O:O,"BUY NOW")>=4, "BULLISH", IF(COUNTIF(Watchlist!O:O,"SELL / AVOID")>=10, "DEFENSIVE", "NEUTRAL")))
L10: Buy Signals | M10: =COUNTIF(Indicators!M:M,"HIGH CONVICTION")
J11: Pullback Entry | L11: Watch | M11: =COUNTIF(Indicators!M:M,"WATCH")
J12: Pullback to 20 or 50 SMA | L12: Avoid | M12: =COUNTIF(Indicators!M:M,"AVOID")
A13: BUY NOW | J13: + First strong green day | L13: Bullish % | M13: =COUNTIF(Indicators!M:M,"HIGH CONVICTION")/(COUNTA(Indicators!A:A)-1)
A14: Symbol | B14: AlphaScore | C14: Return3M | D14: RVOL | E14: Decision | J14: + close above previous day's high
A15: {=IFERROR(_xlfn._xlws.FILTER(TradeDashRankings!B2:B100,TradeDashRankings!N2:N100="HIGH CONVICTION"),"")} | B15: {=IFERROR(_xlfn._xlws.FILTER(TradeDashRankings!K2:K100,TradeDashRankings!N2:N100="HIGH CONVICTION"),"")} | C15: {=IFERROR(_xlfn._xlws.FILTER(TradeDashRankings!G2:G100,TradeDashRankings!N2:N100="HIGH CONVICTION"),"")} | D15: {=IFERROR(_xlfn._xlws.FILTER(TradeDashRankings!F2:F100,TradeDashRankings!N2:N100="HIGH CONVICTION"),"")} | E15: {=IFERROR(_xlfn._xlws.FILTER(TradeDashRankings!N2:N100,TradeDashRankings!N2:N100="HIGH CONVICTION"),"")} | J15: = Buy/Likely bounce | L15: Top Trade Card | Q15: TradeDashRankings
A16: LLY | B16: 100 | C16: 38.8 | D16: 0.1 | E16: HIGH CONVICTION | L16: Symbol | M16: AlphaScore | N16: Return3M | Q16: Rank | R16: Symbol | S16: Alpha | T16: Return3M | U16: RVOL
A17: ABBV | B17: 100 | C17: 33.04 | D17: 0.11 | E17: HIGH CONVICTION | J17: Breakout Entry | L17: =INDEX(_xlfn.ANCHORARRAY(A15),1,1) | M17: =INDEX(_xlfn.ANCHORARRAY(A15),1,2) | N17: =INDEX(_xlfn.ANCHORARRAY(A15),1,3) | Q17: 1 | R17: =TradeDashRankings!B2 | S17: =TradeDashRankings!K2 | T17: =TradeDashRankings!G2 | U17: =TradeDashRankings!F2
A18: AAPL | B18: 100 | C18: 26.44 | D18: 0.21 | E18: HIGH CONVICTION | J18: Resistance at a price (stuck 2-3 times) | Q18: =Q17+1 | R18: =TradeDashRankings!B3 | S18: =TradeDashRankings!K3 | T18: =TradeDashRankings!G3 | U18: =TradeDashRankings!F3
A19: BAC | B19: 100 | C19: 19.69 | D19: 0.23 | E19: HIGH CONVICTION | J19: Break free | L19: Score Guide | Q19: =Q18+1 | R19: =TradeDashRankings!B4 | S19: =TradeDashRankings!K4 | T19: =TradeDashRankings!G4 | U19: =TradeDashRankings!F4
A20: JNJ | B20: 100 | C20: 19.37 | D20: 0.13 | E20: HIGH CONVICTION | J20: Close above resistance price | L20: 90-100 = A+ Setup | Q20: =Q19+1 | R20: =TradeDashRankings!B5 | S20: =TradeDashRankings!K5 | T20: =TradeDashRankings!G5 | U20: =TradeDashRankings!F5
A21: JPM | B21: 100 | C21: 15.04 | D21: 0.12 | E21: HIGH CONVICTION | J21: Volume confirmation (Increasing) | L21: 80-89 = A Setup | Q21: =Q20+1 | R21: =TradeDashRankings!B6 | S21: =TradeDashRankings!K6 | T21: =TradeDashRankings!G6 | U21: =TradeDashRankings!F6
A22: XLF | B22: 100 | C22: 10.26 | D22: 0.2 | E22: HIGH CONVICTION | L22: 70-79 = B Setup | Q22: =Q21+1 | R22: =TradeDashRankings!B7 | S22: =TradeDashRankings!K7 | T22: =TradeDashRankings!G7 | U22: =TradeDashRankings!F7
A23: DDOG | B23: 95 | C23: 88.88 | D23: 0.15 | E23: HIGH CONVICTION | L23: 60-69 = C Setup | Q23: =Q22+1 | R23: =TradeDashRankings!B8 | S23: =TradeDashRankings!K8 | T23: =TradeDashRankings!G8 | U23: =TradeDashRankings!F8
A24: FTNT | B24: 95 | C24: 78.63 | D24: 0.11 | E24: HIGH CONVICTION | L24: <60 = Avoid | Q24: =Q23+1 | R24: =TradeDashRankings!B9 | S24: =TradeDashRankings!K9 | T24: =TradeDashRankings!G9 | U24: =TradeDashRankings!F9
A25: GE | B25: 95 | C25: 26.75 | D25: 0.2 | E25: HIGH CONVICTION | Q25: =Q24+1 | R25: =TradeDashRankings!B10 | S25: =TradeDashRankings!K10 | T25: =TradeDashRankings!G10 | U25: =TradeDashRankings!F10
A26: XLV | B26: 95 | C26: 14.87 | D26: 0.19 | E26: HIGH CONVICTION | L26: RSI Guiude | Q26: =Q25+1 | R26: =TradeDashRankings!B11 | S26: =TradeDashRankings!K11 | T26: =TradeDashRankings!G11 | U26: =TradeDashRankings!F11
L27: 70+ = Overbought
L28: 60-70 = Strong Momentum
L29: 50-60 = Healthy Trend
A30: WATCH FOR ENTRY | L30: 40-50 = Weak Trend
A31: Symbol | B31: AlphaScore | C31: Return3M | D31: RVOL | E31: Decision | L31: <40 = Bearish
A32: {=IFERROR(_xlfn._xlws.FILTER(TradeDashRankings!B2:B100,TradeDashRankings!N2:N100="WATCH"),"")} | B32: {=IFERROR(_xlfn._xlws.FILTER(TradeDashRankings!K2:K100,TradeDashRankings!N2:N100="WATCH"),"")} | C32: {=IFERROR(_xlfn._xlws.FILTER(TradeDashRankings!G2:G100,TradeDashRankings!N2:N100="WATCH"),"")} | D32: {=IFERROR(_xlfn._xlws.FILTER(TradeDashRankings!F2:F100,TradeDashRankings!N2:N100="WATCH"),"")} | E32: {=IFERROR(_xlfn._xlws.FILTER(TradeDashRankings!N2:N100,TradeDashRankings!N2:N100="WATCH"),"")}
A33: OKTA | B33: 85 | C33: 81.69 | D33: 0.09 | E33: WATCH | L33: RVOL Guide
A34: PANW | B34: 85 | C34: 76.27 | D34: 0.11 | E34: WATCH | L34: >2.0 = Heavy Interest
A35: CRWD | B35: 85 | C35: 61.26 | D35: 0.1 | E35: WATCH | L35: 1.2+ = Good Confirmation
L36: 1.0+ = Normal
L37: <1.0 = Weak Participation
L39: ENTRY CHECKLIST
L40: ☐ Score above 80
L41: ☐ RSI above 50
L42: ☐ RVOL above 1.0
L43: ☐ Decision says BUY NOW
L44: ☐ Stop and Target acceptable
...
